<?xml version="1.0"?>

<robot xmlns:xacro="http://www.ros.org/wiki/xacro">

  <xacro:include filename="$(find hector_sensors_description)/urdf/sonar_sensor.urdf.xacro" />
  <xacro:property name="pi" value="3.1415926535897931" />
  <xacro:property name="width" value="0.0315" />
  <xacro:property name="length" value="0.45" />
  <xacro:property name="height" value="0.01" />
  <xacro:property name="mass_fr" value="0.5" />
  <xacro:property name="mass_pr" value="0.0055" />
  <xacro:property name="pi_value" value="3.14159263" />
  <xacro:property name="radiusp" value="0.20" />
  <xacro:property name="prop_loc" value="0.15909" />

  <!-- Main quadrotor link -->
  <xacro:macro name="quadrotor_base_macro">
    <link name="base_link">
      <inertial>
        <mass value="1.95" /> <!-- 1.477 -->
        <origin xyz="0 0 0" />
        <inertia ixx="0.01152" ixy="0.0" ixz="0.0" iyy="0.01152" iyz="0.0" izz="0.0218" />
      </inertial>

      <visual>
        <origin xyz="0 0 0" rpy="0 0 0" />
        <geometry>
          <mesh filename="package://hector_quadrotor_description/meshes/quadrotor/quadrotor_base.dae"/>
        </geometry>
      </visual>

      <collision>
        <origin xyz="0 0 0" rpy="0 0 0" />
        <geometry>
          <mesh filename="package://hector_quadrotor_description/meshes/quadrotor/quadrotor_base.stl"/>
        </geometry>
      </collision>
    </link>

    <!-- Sonar height sensor -->
    <xacro:sonar_sensor name="sonar" parent="base_link" ros_topic="sonar_height" update_rate="10" min_range="0.03" max_range="3.0" field_of_view="${40*pi/180}" ray_count="3">
      <origin xyz="-0.16 0.0 -0.012" rpy="0 ${90*pi/180} 0"/>
    </xacro:sonar_sensor>

  </xacro:macro>
  
  <material name="blue">
    <color rgba="0 0 0.8 1"/>
  </material>

  <material name="white">
    <color rgba="1 1 1 1"/>
  </material>

  <joint name="fixed" type="fixed">
    <parent link="base_link"/>
    <child link="arm1"/>
  </joint>

  <link name="arm1">
    <visual>
      <origin xyz="0.08 0.08 0.0" rpy="1.57 0 -0.785"/>
      <geometry>
	<box size="0.02 0.02 0.2"/>
      </geometry>
      <material name="blue"/>
    </visual>

    <collision>
      <origin xyz="0.08 0.08 0.0" rpy="1.57 0 -0.785"/>
      <geometry>
	<box size="0.02 0.02 0.2"/>
      </geometry>
    </collision>
    <inertial>
      <origin xyz="0.08 0.08 0" rpy="1.57 0 -0.785"/>
      <mass value="0.03" />
      <inertia ixx="1" ixy="0.0" ixz="0.0"
               iyy="1" iyz="0.0"
               izz="1" />
    </inertial>
  </link>

  <!-- Joint between Base Link and Middle Link -->
  <joint name="joint_base_mid" type="revolute">
    <parent link="arm1"/>
    <child link="arm2"/>
    <origin xyz="0.155 0.155 0" rpy="0 0 0"/>
    <axis xyz="0 1 0"/>
    <dynamics damping="0.7"/>
    <limit effort="100.0" velocity="0.5" lower="-3.14" upper="3.14" />
  </joint>

  <!-- Middle Link -->
  <link name="arm2">
    <visual>
      <origin xyz="0.03 0.03 0" rpy="1.57 0 -0.785"/>
      <geometry>
	<box size="0.02 0.02 0.1"/>
      </geometry>
      <material name="white"/>
    </visual>

    <collision>
      <origin xyz="0.03 0.03 0" rpy="1.57 0 -0.785"/>
      <geometry>
	<box size="0.02 0.02 0.1"/>
      </geometry>
    </collision>
    <inertial>
      <origin xyz="0.03 0.03 0.0" rpy="1.57 0 -0.785"/>
      <mass value="0.015" />
      <inertia ixx="1" ixy="0.0" ixz="0.0"
               iyy="1" iyz="0.0"
               izz="1" />
    </inertial>
  </link>

  <!-- Joint between Middle Link and Top Link -->
  <joint name="joint_mid_top" type="revolute"> 
    <parent link="arm2"/>
    <child link="arm3"/>
    <origin xyz="0.07 0.07 0.0" rpy="0 0 0"/>
    <axis xyz="0 1 0"/> 
    <dynamics damping="0.7"/> 
    <limit effort="100.0" velocity="0.5" lower="-3.14" upper="3.14" />
  </joint>

  <!-- Top Link -->
  <link name="arm3">
    <visual>
      <origin xyz="0.03 0.03 0.0" rpy="1.57 0 -0.785"/>
      <geometry>
	<box size="0.02 0.02 0.1"/>
      </geometry>
      <material name="blue"/>
    </visual>

    <collision>
      <origin xyz="0.03 0.03 0.0" rpy="1.57 0 -0.785"/>
      <geometry>
	<box size="0.02 0.02 0.1"/>
      </geometry>
    </collision>
    <inertial>
      <origin xyz="0.03 0.03 0.0" rpy="1.57 0 -0.785"/>
      <mass value="0.015" />
      <inertia ixx="1" ixy="0.0" ixz="0.0"
               iyy="1" iyz="0.0"
               izz="1" />
    </inertial>
  </link>

  <transmission name="transmission1">
    <type>transmission_interface/SimpleTransmission</type>
    <joint name="joint_base_mid">
      <hardwareInterface>EffortJointInterface</hardwareInterface>
    </joint>
    <actuator name="motor1">
      <hardwareInterface>EffortJointInterface</hardwareInterface>
      <mechanicalReduction>1</mechanicalReduction>
    </actuator>
  </transmission>

  <transmission name="transmission2">
    <type>transmission_interface/SimpleTransmission</type>
    <joint name="joint_mid_top">
      <hardwareInterface>EffortJointInterface</hardwareInterface>
    </joint>
    <actuator name="motor2">
      <hardwareInterface>EffortJointInterface</hardwareInterface>
      <mechanicalReduction>1</mechanicalReduction>
    </actuator>
  </transmission>

  <gazebo reference="arm1">
    <material>Gazebo/Red</material>
  </gazebo>

  <!-- Middle Link -->
  <gazebo reference="arm2">
    <material>Gazebo/White</material>
  </gazebo>

  <!-- Top Link -->
  <gazebo reference="arm3">
    <material>Gazebo/Blue</material>
  </gazebo>

<!-- Im starting the new arms here -->
  <joint name="fixed1" type="fixed">
    <parent link="base_link"/>
    <child link="arm4"/>
  </joint>

  <link name="arm4">
    <visual>
      <origin xyz="-0.08 -0.08 0.0" rpy="-1.57 0 -0.785"/>
      <geometry>
	<box size="0.02 0.02 0.2"/>
      </geometry>
      <material name="blue"/>
    </visual>

    <collision>
      <origin xyz="-0.08 -0.08 0.0" rpy="-1.57 0 -0.785"/>
      <geometry>
	<box size="0.02 0.02 0.2"/>
      </geometry>
    </collision>
    <inertial>
      <origin xyz="-0.08 -0.08 0" rpy="-1.57 0 -0.785"/>
      <mass value="0.03" />
      <inertia ixx="1" ixy="0.0" ixz="0.0"
               iyy="1" iyz="0.0"
               izz="1" />
    </inertial>
  </link>

  <!-- Joint between Base Link and Middle Link -->
  <joint name="joint_base_mid_two" type="revolute">
    <parent link="arm4"/>
    <child link="arm5"/>
    <origin xyz="-0.155 -0.155 0" rpy="0 0 0"/>
    <axis xyz="0 1 0"/>
    <dynamics damping="0.7"/>
    <limit effort="100.0" velocity="0.5" lower="-3.14" upper="3.14" />
  </joint>

  <!-- Middle Link -->
  <link name="arm5">
    <visual>
      <origin xyz="-0.03 -0.03 0" rpy="-1.57 0 -0.785"/>
      <geometry>
	<box size="0.02 0.02 0.1"/>
      </geometry>
      <material name="white"/>
    </visual>

    <collision>
      <origin xyz="-0.03 -0.03 0" rpy="-1.57 0 -0.785"/>
      <geometry>
	<box size="0.02 0.02 0.1"/>
      </geometry>
    </collision>
    <inertial>
      <origin xyz="-0.03 -0.03 0.0" rpy="-1.57 0 -0.785"/>
      <mass value="0.015" />
      <inertia ixx="1" ixy="0.0" ixz="0.0"
               iyy="1" iyz="0.0"
               izz="1" />
    </inertial>
  </link>

  <!-- Joint between Middle Link and Top Link -->
  <joint name="joint_mid_top_two" type="revolute"> 
    <parent link="arm5"/>
    <child link="arm6"/>
    <origin xyz="-0.07 -0.07 0.0" rpy="0 0 0"/>
    <axis xyz="0 1 0"/> 
    <dynamics damping="0.7"/> 
    <limit effort="100.0" velocity="0.5" lower="-3.14" upper="3.14" />
  </joint>

  <!-- Top Link -->
  <link name="arm6">
    <visual>
      <origin xyz="-0.03 -0.03 0.0" rpy="-1.57 0 -0.785"/>
      <geometry>
	<box size="0.02 0.02 0.1"/>
      </geometry>
      <material name="blue"/>
    </visual>

    <collision>
      <origin xyz="-0.03 -0.03 0.0" rpy="-1.57 0 -0.785"/>
      <geometry>
	<box size="0.02 0.02 0.1"/>
      </geometry>
    </collision>
    <inertial>
      <origin xyz="-0.03 -0.03 0.0" rpy="-1.57 0 -0.785"/>
      <mass value="0.015" />
      <inertia ixx="1" ixy="0.0" ixz="0.0"
               iyy="1" iyz="0.0"
               izz="1" />
    </inertial>
  </link>

  <transmission name="transmission3">
    <type>transmission_interface/SimpleTransmission</type>
    <joint name="joint_base_mid_two">
      <hardwareInterface>EffortJointInterface</hardwareInterface>
    </joint>
    <actuator name="motor3">
      <hardwareInterface>EffortJointInterface</hardwareInterface>
      <mechanicalReduction>1</mechanicalReduction>
    </actuator>
  </transmission>

  <transmission name="transmission4">
    <type>transmission_interface/SimpleTransmission</type>
    <joint name="joint_mid_top_two">
      <hardwareInterface>EffortJointInterface</hardwareInterface>
    </joint>
    <actuator name="motor4">
      <hardwareInterface>EffortJointInterface</hardwareInterface>
      <mechanicalReduction>1</mechanicalReduction>
    </actuator>
  </transmission>

  <gazebo reference="arm4">
    <material>Gazebo/Red</material>
  </gazebo>

  <!-- Middle Link -->
  <gazebo reference="arm5">
    <material>Gazebo/White</material>
  </gazebo>

  <!-- Top Link -->
  <gazebo reference="arm6">
    <material>Gazebo/Blue</material>
  </gazebo>

</robot>
